Workbook

Sheet Partner Ratios and Funding
A1: Builder Funding Closing Amount | C1: 475000
A5: Kirit | B5: 0.25 | C5: =C1*B5 -> 118750
A6: Nilesh | B6: 0.25 | C6: =C1*B6 -> 118750
A7: Kunal | B7: 0.2 | C7: =C1*B7 -> 95000
A8: Swekit | B8: 0.2 | C8: =C1*B8 -> 95000 | J8: =2000*0.03 -> 60
A9: Maulik | B9: 0.1 | C9: =C1*B9 -> 47500
J11: =575*3 -> 1725
B12: =SUM(B5:B11) -> 1 | C12: 475000 | J12: =1725+300 -> 2025
A14: Funding | B14: 475000
A17: Date | B17: Amount Deposited
B18: Kirit | C18: Kunal | D18: Nilesh | E18: Maulik | F18: Swekit | G18: Oak Tree | H18: JSQ | L18: 1750
A19: 45404 | B19: 20000 | I19: =sum(B19:F19) -> 20000 | L19: 150
A20: 45405 | E20: 40000 | I20: =sum(B20:F20) -> 40000 | L20: 1210
A21: 45419 | B21: 80000 | C21: 80000 | D21: 100000 | F21: 80000 | I21: =sum(B21:F21) -> 340000 | L21: 500
A22: 45433 | H22: 10000 | I22: -10000 | M22: *
A23: 45467 | H23: -10153.5 | I23: 10153.5 | L23: 300
A24: 45495 | B24: 10000 | I24: =sum(B24:F24) -> 10000
A25: 45554 | E25: 2500 | I25: =sum(B25:F25) -> 2500
A26: 45558 | C26: 5000 | I26: =sum(B26:F26) -> 5000
A27: 45573 | F27: 5000 | I27: =sum(B27:F27) -> 5000
A28: 45586 | B28: 6250 | I28: =sum(B28:F28) -> 6250
A29: 45586 | E29: 2500 | I29: =sum(B29:F29) -> 2500
A30: 45604 | G30: 58857.25 | I30: 58857.25
A31: 45630 | G31: 83599 | I31: 83599
A32: 45656 | H32: 5000 | I32: 5000
A33: 45646 | H33: -5000 | I33: -5000
A34: 45678 | H34: 1000 | I34: 1000
A35: 45693 | G35: 87925 | I35: 87925
A36: 45728 | G36: 71325 | I36: 71325
A37: 45769 | G37: 86825 | I37: 86825
A38: 45804 | G38: 108325
A39: 45831 | H39: -10847.29
A40: 45853 | G40: 38274
A41: 45890 | C41: -3000
A42: 45902 | G42: 29825
A43: 45903 | C43: 3000
A44: 45922 | G44: 26325
A45: 45922 | C45: 20000
A46: 45926 | C46: -20000
A47: 45932 | B47: 12500 | F47: 10000
...

Sheet Soft Cost
A1: Date | B1: Mode | C1: Description | D1: Amount
A2: 45517 | C2: Total Wine 306 | D2: 12.78 | F2: Total | G2: =sum(D2:D999998) -> 171.88
A3: 45519 | C3: Imperial 46 Restaurant | D3: 38.64
A4: 45558 | C4: Saj Restaurant Paterson | D4: 120.46

Sheet Total Expenses
A1: SR. NO | B1: Type | C1: Amount
A2: 1 | B2: Construction Cost | C2: ='Construction Expenses'!G1 -> 848210.56
A3: 2 | B3: Bank fees | C3: ='Bank fees'!G2 -> 191.6
A4: 3 | B4: Muncipality | C4: ='Muncipality Expenses'!G1 -> 6398.25 | F4: =sum(C2+C3+C7+C8+C9+C10) -> 1027446
A5: 4 | B5: Land Acquisition | C5: ='Land acquisition'!F2 -> 377367.94 | H5: 715
A6: 5 | B6: Loan payments | C6: ='Loan Payment'!F2 -> 152379.49 | H6: 129
A7: 6 | B7: Miscellaneous | C7: =Misc.!G2 -> 2923.95 | D7: =sum(C2+C8) -> 1021608.6 | L7: 500 | N7: 1900
A8: 7 | B8: Labour | C8: =Labour!G1 -> 173398 | L8: 550 | N8: =N7*0.07 -> 133
A9: 8 | B9: Soft Cost | C9: ='Soft Cost'!G2 -> 171.88 | L9: 550 | N9: =N7-N8 -> 1767
A10: 9 | B10: Accounting & Legal Fee | C10: ='Accounting & Legal'!G1 -> 2550 | L10: 300
E11: =C14-C5 -> 1186223.7 | I11: =C14-C5 -> 1186223.7
B14: Total Cost of Project | C14: =sum(C2:C10) -> 1563591.7
G15: =sum(C14-C5) -> 1186223.7
E16: =C14-C5 -> 1186223.7
E18: =C14-C5-C6 -> 1033844.2

Sheet Unit Sold
A2: Date | B2: Unit # | C2: Sell Price | D2: Closing Cost | E2: Loan Pay off | F2: Deposit | G2: Net Distribution
G3: =sum(C3-D3-E3)+F3 -> 0
G4: =sum(C4-D4-E4)+F4 -> 0
G5: =sum(C5-D5-E5)+F5 -> 0
B6: Total | C6: =sum(C3:C5) -> 0 | D6: =sum(D3:D5) -> 0 | E6: =sum(E3:E5) -> 0 | F6: =sum(F3:F5) -> 0 | G6: =sum(C6-D6-E6) -> 0

Sheet Labour
A1: Date | B1: Mode | C1: Description | D1: Amount | F1: Total | G1: =sum(D4:D9991) -> 173398 | H1: 2025 Total | I1: =sum(D40:D221) -> 91388.85
A2: 45597 | B2: Check 1241 | C2: Nilson Mocalos | D2: 155
A3: 45597 | B3: Check 1243 | C3: Milton son | D3: 155
A4: 45611 | B4: Check 1054 | C4: Nilson Mocalos | D4: 1280
A5: 45611 | B5: Check 1059 | C5: Milton son | D5: 950
A6: 45614 | B6: Check 1056 | C6: Carlos Chipix | D6: 695
A7: 45614 | B7: Check 1057 | C7: Javier Alejandro Omaza | D7: 545
A8: 45614 | B8: Check 1058 | C8: Jorbe Pervalo | D8: 405
A9: 45614 | B9: Check 1061 | C9: Juan Minin | D9: 310 | E9: '
A10: 45615 | B10: Check 1060 | C10: Frank Verbout | D10: 700
A11: 45621 | B11: Check 1055 | C11: Jose Lopez | D11: 465
A12: 45625 | B12: Check 1004 | C12: Javier Alejandro Omaza | D12: 410
A13: 45625 | B13: Check 1010 | C13: Nilson Mocalos | D13: 580
A14: 45625 | B14: Check 1012 | C14: Jorbe Pervalo | D14: 405
A15: 45628 | B15: Check 1011 | C15: Carlos Chipix | D15: 280
A16: 45628 | B16: Check 1014 | C16: Crisanto Cum Plato | D16: 210
A17: 45628 | B17: Check 1015 | C17: Juan Minin | D17: 165
A18: 45628 | B18: Check 1013 | C18: Luis Angle | D18: 270
A19: 45629 | B19: Check 1005 | C19: Jose Lopez | D19: 310
A20: 45630 | B20: Check 1067 | C20: Milton son | D20: 525
A21: 45632 | B21: Check 1068 | C21: Darwin Cutzal | D21: 135
... A45: 45670 | B45: Check 1017 | C45: Nilson Mocalos | D45: 480
A46: 45670 | B46: Check 1018 | C46: Rene Cutzal | D46: 405 | E46: d
A47: 45670 | B47: Check 1042 | C47: Jorbe Pervalo | D47: 1080
A48: 45672 | B48: Check 1041 | C48: Carlos Cipix | D48: 280
A49: 45678 | B49: Check 1009 | C49: Luis Angle | D49: 1080
A50: 45684 | B50: Check 1045 | C50: Luis Angle | D50: 675
A51: 45684 | B51: Check 1047 | C51: Jorbe Pervalo | D51: 675
A52: 45684 | B52: Check 1044 | C52: Javier Alejandro Omaza | D52: 465
A53: 45684 | B53: Check 1050 | C53: Nilson Mocalos | D53: 640
A54: 45684 | B54: Check 1090 | C54: Christian Ponte | D54: 720
A55: 45684 | B55: Check 1091 | C55: Edwin Espana | D55: 435
A56: 45686 | B56: Check 1088 | C56: Rene Cutzal | D56: 560
A57: 45691 | B57: Check 1049 | C57: Jose Gonzales | D57: 135 | E57: d
A58: 45691 | B58: Check 61089 | C58: Darwin Cutzal | D58: 1015 | E58: d
A59: 45695 | B59: Check 1097 | C59: Nilson Mocalos | D59: 208 | E59: d
A60: 45695 | B60: Check 1096 | C60: Nilson Mocalos | D60: 412 | E60: d
A61: 45698 | B61: Check 1095 | C61: Carlos Cutzal | D61: 590 | E61: d
A62: 45698 | B62: Check 1103 | C62: Javier Alejandro Omaza | D62: 465 | E62: d
A63: 45698 | B63: Check 1105 | C63: Carlos Cipix | D63: 420 | E63: d
...

Sheet Construction Expenses
A1: Date | B1: Mode | C1: Description | D1: Amount | F1: Total | G1: =sum(D3:D10010) -> 848210.56 | H1: 2025 Total | I1: =sum(D22:D109) -> 589709.4
A2: 45414 | B2: Wire | C2: RA Design & Consultants | D2: 4500
A3: 45495 | B3: Amex | C3: Kunal Amex Payment | D3: 20173.95
A4: 45516 | B4: Credit | C4: Counter Credit | D4: -93
A5: 45555 | B5: Amex | C5: Kunal Amex Payment | D5: 2389.77
A6: 45586 | B6: Amex | C6: Kunal Amex Payment | D6: 15140.26
A7: 45588 | B7: Check 1037 | C7: Cash | D7: 180
A8: 45609 | B8: Card 7162 | C8: Amazon | D8: 88.6
A9: 45617 | B9: Amex | C9: Kunal Amex Payment | D9: 34753.53
A10: 45608 | B10: Check 1053 | C10: Jeremy Verbout | D10: 1250
A11: 45617 | B11: Check 1062 | C11: O.E.A | D11: 350
A12: 45623 | B12: Check 1063 | C12: Tomich Siding | D12: 1500
A13: 45622 | B13: Check 1065 | C13: RVC Construction | D13: 5760
... A21: 45653 | B21: Check 1081 | C21: Tomich | D21: 1000
A22: 45663 | B22: Check 1040 | C22: Jeremy Verbout | D22: 500 | E22: d
A23: 45663 | B23: Check 1046 | C23: Frank Verbout | D23: 3000 | E23: d
A24: 45670 | B24: Check 1043 | C24: Level Five | D24: 1500 | E24: d
A25: 45678 | B25: Credit | C25: Online Transfer 6298 | D25: -214.83 | E25: d
A26: 45678 | B26: Amex | C26: Kunal Amex Payment | D26: 17094.91 | E26: d
A27: 45684 | B27: Check 1046 | C27: Frank Verbout | D27: 3000 | E27: d
A28: 45688 | B28: Check 1094 | C28: E8v Dirtwork | D28: 5100 | E28: d
A29: 45691 | B29: Check 1092 | C29: Jeremy Verbout | D29: 1500 | E29: d
A30: 45692 | B30: Check 1093 | C30: Frank Verbout | D30: 3000 | E30: d
A31: 45693 | B31: Check 1034 | C31: Dhruv Kansara | D31: 569.4 | E31: d
A32: 45706 | B32: Wire | C32: Guandong PA Home | D32: 8996.55 | E32: d
A33: 45708 | B33: Amex | C33: Kunal Amex Payment | D33: 17733.13 | E33: d
... A109: 46020 | B109: Check 1294 | C109: Vulcan Innovation LLC | D109: 250 | E109: d
A110: 46021 | B110: Check 1329 | C110: No Check | D110: 732
A111: 46022 | B111: Credit | C111: Return of Check | D111: -732
A112: 46043 | B112: Amex | C112: Kunal Amex Payment | D112: 11729.44
A113: 46034 | B113: Check 1332 | C113: Moda Tiles | D113: 12210
A114: 46031 | B114: Check 1334 | C114: Vulcan Innovation LLC | D114: 700
A115: 46035 | B115: Check 1342 | C115: IOS Hardwood Floor | D115: 2190
A116: 46045 | B116: Check 1345 | C116: Vulcan Innovation LLC | D116: 750
A117: 46056 | B117: Check 1348 | C117: Vulcan Innovation LLC | D117: 3000
A118: 46056 | B118: Check 1349 | C118: Vulcan Innovation LLC | D118: 750
A119: 46062 | B119: Check 1354 | C119: Vulcan Innovation LLC | D119: 1250
A120: 46076 | B120: Check 1358 | C120: American Marble & Granite | D120: 1900
A121: 46106 | B121: Debit | C121: Amercan Express | D121: 12675.17
... A128: 46121 | B128: Check 1402 | C128: Vulcan Innovation LLC | D128: 500
...

Sheet Accounting & Legal
A1: Date | B1: Mode | C1: Description | D1: Amount | F1: 2025 Total | G1: =sum(D2:D9999) -> 2550
A2: 45659 | B2: Check1001 | C2: Ami Shah CPA | D2: 650 | E2: d
A3: 45714 | B3: Wire | C3: Ami Shah CPA | D3: 850 | E3: d
A4: 46020 | B4: Wire | C4: Ami Shah CPA | D4: 400 | E4: d
A5: 46021 | B5: Credit | C5: Return of Check | D5: -400 | E5: d
A6: 46205 | B6: Debit | C6: Ami Shah CPA | D6: 1050

Sheet Bank fees
A1: Date | B1: Description | C1: Amount | H1: 2025 Total | I1: =sum(C3:C14) -> 74.4
A2: 45432 | B2: Wire Transfer Fee | C2: 30 | F2: Total | G2: =SUM(C2:C1004) -> 191.6
A3: 45659 | B3: Excess Transation Fee | C3: 4.5
A4: 45691 | B4: Excess Transation Fee | C4: 1.8
A5: 45719 | B5: Excess Transation Fee | C5: 3.15
A6: 45748 | B6: Excess Transation Fee | C6: 0.9
A7: 45810 | B7: Excess Transation Fee | C7: 3.15
A8: 45891 | B8: Overdraft Fee | C8: 10 | D8: d
A9: 45894 | B9: Overdraft Fee | C9: 10 | D9: d
A10: 45966 | B10: Overdraft Fee | C10: 10 | D10: d
A11: 45992 | B11: Overdraft Fee | C11: 10
A12: 45992 | B12: Excess Transation Fee | C12: 0.9
A13: 46020 | B13: Overdraft Fee | C13: 10
A14: 46022 | B14: Overdraft Fee | C14: 10
A15: 46085 | B15: Wire Transfer Fee | C15: 30
A16: 46143 | B16: Excess Transation Fee | C16: 5.85
A17: 46150 | B17: Wire Transfer Fee | C17: 30
A18: 46174 | B18: Excess Transation Fee | C18: 1.35
A19: 46239 | B19: Overdraft Fee | C19: 10
A20: 46244 | B20: Overdraft Fee | C20: 10

Sheet Land acquisition
A1: Date | B1: Description | C1: Amount
A2: 45406 | B2: Withdrawal | C2: 20000 | E2: Total | F2: =sum(C2:C999) -> 377367.94
A3: 45432 | B3: Withdrawal | C3: 357367.94
O21: 110000

Sheet Muncipality Expenses
A1: Date | B1: Mode | C1: Description | D1: Amount | F1: Total | G1: =sum(D3:D10004) -> 6398.25 | H1: 2025 Total | I1: =sum(D8:D12) -> 2785.46
A2: 45467 | B2: Wire | C2: Passaic Valley Sewage | D2: 4229.5
A3: 45481 | C3: Nj Gov ServEw | D3: 101
A4: 45504 | C4: Jersey City Tax Payment | D4: 968.58
A5: 45504 | C5: Jersey City CFee | D5: 0.5
A6: 45590 | C6: Jersey City Tax Payment | D6: 1384.46
A7: 45590 | C7: Jersey City CFee | D7: 0.5
A8: 45692 | C8: Jersey City Tax Payment | D8: 1384.46 | E8: d
A9: 45692 | C9: Jersey City CFee | D9: 0.5 | E9: d
A10: 45726 | B10: Debit | C10: NJ web PMT | D10: 1125 | E10: d
A11: 45860 | B11: Check 1028 | C11: State of New Jersey | D11: 200 | E11: d
A12: 46022 | B12: Debit | C12: NJ web PMT | D12: 75.5 | E12: d
A13: 46036 | C13: NJ web PMT | D13: 6.25
A14: 46043 | B14: Check 1019 | C14: State of New Jersey | D14: 200
A15: 46091 | C15: NJ web PMT | D15: 750
A16: 46260 | C16: NJ web PMT | D16: 201.5

Sheet Loan Payment
A1: Date | B1: Description | C1: Amount
A2: 45674 | B2: FCI Loan Payment | C2: 1695.54 | E2: 2025 Total | F2: =sum(C2:C9998) -> 152379.49
A3: 45695 | B3: BSI Finance | C3: 1784.55
A4: 45729 | B4: BSI Finance | C4: 2595.81 | D4: d
A5: 45754 | B5: BSI Finance | C5: 3201.75 | D5: d
A6: 45782 | B6: BSI Finance | C6: 3757.61 | D6: d
A7: 45813 | B7: BSI Finance | C7: 4558.39 | D7: d
A8: 45846 | B8: BSI Finance | C8: 5557.49 | D8: d
A9: 45874 | B9: BSI Finance | C9: 5775.37 | D9: d
A10: 45905 | B10: BSI Finance | C10: 5966.01 | D10: d
A11: 45936 | B11: BSI Finance | C11: 6358.61 | D11: d
A12: 45966 | B12: BSI Finance | C12: 6802.9 | D12: d
A13: 45996 | B13: BSI Finance | C13: 7275.01 | D13: d
A14: 46027 | B14: BSI Finance | C14: 7983.13
A15: 46076 | B15: BSI Finance | C15: 10066.08
A16: 46097 | B16: BSI Finance | C16: 11763.27
A17: 46118 | B17: BSI Finance | C17: 10474.89
A18: 46147 | B18: BSI Finance | C18: 10528.6
A19: 46155 | B19: BSI Finance | C19: 3092.27
A20: 46185 | B20: bsI Finance | C20: 22083.24
A21: 46209 | B21: Bsi Finance | C21: 10532.73
A22: 46239 | B22: Bsi Finance | C22: 10526.24

Sheet Misc.
A1: Date | B1: Mode | C1: Description | D1: Amount
A2: 45665 | B2: Check 1003 | C2: Friend Of Anand Shah | D2: 500 | F2: Total | G2: =sum(D2:D9995) -> 2923.95
A3: 45922 | B3: credit | C3: Sav 7614 | D3: -20000
A4: 45926 | B4: Debit | C4: Sav 7614 | D4: 20000
A5: 46059 | B5: credit | C5: Return of Check | D5: -8941.05
A6: 46105 | B6: Credit | C6: chk 0529 | D6: -4000
A7: 46087 | B7: Credit | C7: Return of Check | D7: -9139
A8: 46105 | B8: Credit | C8: Return of Check | D8: -12675.17
A9: 46112 | B9: Credit | C9: Return of Check | D9: -5000
A10: 46086 | B10: Debit | C10: Bsi Finance | D10: 9139
A11: 46083 | B11: Debit | C11: CHK6139 | D11: 15000
A12: 46104 | B12: Debit | C12: American Express | D12: 12675.17
A13: 46111 | B13: Debit | C13: Check washout | D13: 5000
A14: 46149 | B14: Credit | C14: Return of Check | D14: -4000
... A19: 46148 | B19: Debit | C19: Check 1436 | D19: 4000
