Workbook

Sheet Partner Ratios and Funding
A2: 800000
W3: 650
W4: 600
A5: Kunal Shah | B5: 0.1 | C5: =sum(A2*B5) -> 80000 | W5: 50
A6: Swekit Patel | B6: 0.1 | C6: =sum(A2*B6) -> 80000
A7: Harshad Patel | B7: 0.45 | C7: =sum(A2*B7) -> 360000
A8: Kirit Chothani | B8: 0.15 | C8: =sum(A2*B8) -> 120000
A9: Nilesh Chothani | B9: 0.1 | C9: =B9*A2 -> 80000
A10: Vijay Soni | B10: 0.1 | C10: 80000
B11: =SUM(B5:B10) -> 1 | C11: 800000
T12: 45236 | U12: 350000 | V12: divided to Kunal, Swekit and Harshad
T13: 45301 | U13: 175000 | V13: divided to Kunal, Swekit and Harshad
A16: Date | D16: Amount Deposited
B17: Kunal Shah | C17: Swekit Patel | D17: Harshad Patel | E17: Kirit Chothani | F17: Nilesh Chothani | G17: Vijay Soni
A18: 45236 | B18: 0 | C18: 0 | D18: 0 | M18: =350000/3 -> 116666.67 | P18: 3100000 | Q18: Sale
A19: 45295 | C19: 0 | E19: 75000 | P19: 375000 | Q19: Down payment Lender
A20: 45296 | F20: 50000 | P20: 700000 | Q20: Construction
A21: 45301 | B21: 0 | C21: 0 | D21: 0 | E21: 30000 | F21: 20000 | P21: =P18*0.05 -> 155000 | Q21: Comm
A22: 45918 | G22: 80000
A23: 45558 | E23: 15000 | J23: =175*3 -> 525 | P23: 90000 | Q23: Peter Interest
A24: 45930 | D24: 525000 | K24: =800*0.75 -> 600
A25: 45566 | D25: 25000
A26: 45567 | B26: -80000 | C26: -80000 | D26: 160000 | K26: 700*.75
A27: 45644 | C27: -15000 | K27: =700*0.75 -> 525
A28: 45650 | B28: -15000
A29: 45684 | B29: 0 | J29: =800*0.45 -> 360
A30: 45992 | B30: 20000
A31: 46083 | F31: 10000
A32: 46083 | B32: -20000
A33: 46093 | B33: -80000 | C33: -80000
A34: 46111 | D34: -525000
A35: 46115 | E35: -120000 | F35: -80000
A36: 46118 | F36: 80000
A37: 46119 | B37: 80000
A38: 46120 | D38: -160000
A39: 46134 | D39: -112500
A40: 46136 | F40: 25000
A41: 46209 | E41: -29526.34 | F41: -19684.23
A42: 46211 | C42: 30000
A43: 46268 | B43: 100000
...

Sheet Unit Sold
A2: Unit # | B2: Sell Price | C2: Closing Cost | D2: Loan Pay off | E2: Deposit | F2: Net Distribution
A3: 3 | B3: 1502251.1 | C3: 132315.75 | D3: 1357084.8 | F3: =sum(B3-C3-D3)+E3 -> 12850.49
A4: 2 | B4: 800947.05 | C4: 49317.15 | D4: 0 | E4: 79900 | F4: =sum(B4-C4-D4)+E4 -> 831529.9
A5: 1 | B5: 856012.37 | C5: 61466 | D5: 0 | E5: 0 | F5: =sum(B5-C5-D5)+E5 -> 794546.37
A6: Total | B6: =sum(B3:B5) -> 3159210.5 | C6: =sum(C3:C5) -> 243098.9 | D6: =sum(D3:D5) -> 1357084.8 | E6: =sum(E3:E5) -> 79900 | F6: =sum(B6-C6-D6) -> 1559026.8
A10: Sale Price | B10: =B6 -> 3159210.5
A11: Expenses | B11: =sum('Total Expenses'!C3+'Total Expenses'!C4+'Total Expenses'!C5+'Total Expenses'!C7+'Total Expenses'!C8) -> 1260899.6
A12: Land Cost | B12: ='Total Expenses'!C2 -> 1100000
A13: Interest | B13: ='Total Expenses'!C6+'Total Expenses'!C11 -> 281177.22
A14: Closing Costs | B14: ='Total Expenses'!C9+'Total Expenses'!C10 -> 325798.9
A15: Gross Profit | B15: =sum(B10-(B11+B12+B13+B14)) -> 191334.83
A16: Paul 25% | B16: =B15*0.25 -> 47833.707
A17: Net Distribution | B17: =sum(B15-B16) -> 143501.12
A19: Investment | B19: 800000
A20: Return on Investment | B20: =B17 -> 143501.12
A21: ROI% | B21: =B20/B19 -> 0.1793764

Sheet Inner Bank Transfer
A2: Date
B3: Capex Capital | C3: Ks Builders | D3: 210 Fulton | E3: SV FUTURE | F3: F.C.I | G3: Shiv Dhruv | H3: Forked River | I3: 317 Summit | J3: JC Venture | K3: 146 Academy | L3: Acepoint | M3: 203 Danforth | N3: 96 Clerk
A4: 45390 | B4: 10000
A5: 45393 | B5: 10000
A6: 45397 | B6: 10000
A7: 45401 | B7: -30000
A8: 45534 | F8: 22670
A9: 45538 | B9: 10000
A10: 45918
A11: 45572 | F11: 80770
A12: 45602 | F12: 103370
A13: 45628 | B13: 10000
A14: 45628 | B14: 20000
A15: 45646 | B15: 1000
A16: 45649 | B16: 15000
A17: 45678 | B17: -1000
A18: 45679 | B18: -10000
A19: 45684 | B19: -10000
A20: 45692 | B20: -10000
A21: 45695 | F21: 79770
A22: 45714 | B22: 10000
A23: 45723 | B23: -20000
A24: 45733 | F24: 20770
A25: 45733 | F25: 65270
A26: 45740 | B26: -3000
A27: 45743 | B27: -10000
A28: 45747 | B28: -2000
A29: 45749 | F29: 89670
A30: 45776 | B30: -20000
A31: 45783 | F31: 46320
A32: 45805 | B32: -10000
A33: 45807 | B33: -20000
A34: 45819 | F34: 24970
A35: 45831 | D35: -17160.11
A36: 45838 | C36: -6300
A37: 45839 | C37: -10000
A38: 45847 | B38: -20000
A39: 45854 | F39: 34620
A40: 45859 | B40: -38500
A41: 45867 | B41: -30000
...

Sheet Total Expenses
A1: SR. NO | B1: Type | C1: Amount | E1: 4 | F1: Land Acquisition | G1: ='Land acquisition'!F2 -> 624823.01
B2: Land Cost | C2: 1100000
A3: 1 | B3: Construction Cost + Labor | C3: =sum('Construction '!G2+Labour!G1) -> 1228905.3
A4: 2 | B4: Bank fees | C4: ='Bank fees'!G2 -> 890
A5: 3 | B5: Muncipality | C5: ='Muncipality Expenses'!F2 -> 27538.5
A6: 5 | B6: Interest payments | C6: ='Loan Payment'!F3 -> 268177.22
A7: 6 | B7: Miscellaneous | C7: =Misc.!G1 -> 65.77
A8: 8 | B8: Accounting & Legal fee | C8: ='Accounting &legal fee'!G2 -> 3500
A9: 9 | B9: Closing Costs (Purchase) | C9: 82700
A10: 10 | B10: Closing Costs(Sale) | C10: ='Unit Sold'!C6 -> 243098.9
A11: 11 | B11: Amex Interest to Capex | C11: 13000
B13: Total Cost of Project | C13: =sum(C1:C12) -> 2967875.7

Sheet Expense CC
A1: Date | B1: Receipt | C1: Description | D1: Card Member | E1: Account # | F1: Amount
A2: 45494 | C2: WAWA FUEL/CONVENIENCKEARNY NJ | D2: DHRUMI SHAH | E2: -1038 | F2: 33.2
A3: 45491 | C3: WAWA FUEL/CONVENIENCKEARNY NJ | D3: DHRUMI SHAH | E3: -1038 | F3: 40
A4: 45488 | C4: FUEL 4 JERSEY CITY JERSEY CITY NJ | D4: DHRUMI SHAH | E4: -1038 | F4: 40
A5: 45487 | C5: THE HOME DEPOT CLIFTON NJ | D5: DHRUMI SHAH | E5: -1038 | F5: 52.53
A6: 45484 | C6: WAWA FUEL/CONVENIENCKEARNY NJ | D6: DHRUMI SHAH | E6: -1038 | F6: 40
A7: 45482 | C7: TICK TOCK DINER CLIFTON NJ | D7: DHRUMI SHAH | E7: -1038 | F7: 44.01
A8: 45479 | C8: QUICK CHEK CORPORATIBELLEVILLE NJ | D8: DHRUMI SHAH | E8: -1038 | F8: 40

Sheet Construction 
A1: Date | B1: Description | C1: Description | D1: Amount | E1: Description
A2: 45274 | B2: Debit | C2: Wire Transfer RA Design and Consultants | D2: 12500 | F2: Total | G2: =sum(D2:D9996) -> 1010251.1
A3: 45301 | B3: Debit | C3: Land | D3: 300
A4: 45310 | B4: Amex | C4: Kunal Amex | D4: 1245
A5: 45344 | B5: Amex | C5: Kunal Amex | D5: 377.17
A6: 45370 | B6: Check 2001 | C6: Dynasty Protection | D6: 3000
A7: 45372 | B7: Check 2002 | C7: Expidator CASH | D7: 1000
A8: 45384 | B8: Credit | C8: Undo Wire transfer Vulcon | D8: -3112.5
A9: 45384 | B9: Debit | C9: Wire transfer Vulcon | D9: 3112.5
A10: 45404 | B10: Amex | C10: Kunal Amex | D10: 1396.23
A11: 45404 | B11: Check 2007 | C11: OEA | D11: 1350
A12: 45405 | B12: Check 2010 | C12: Robert Hogan | D12: 600
A13: 45434 | B13: Amex | C13: Kunal Amex | D13: 16957.73
A14: 45485 | B14: Check 2022 | C14: DEP | D14: 2000
... A130: 46010 | B130: Debit | C130: 2754 to 3448 | D130: 22433.72
A131: 46006 | B131: Withdrawal | C131: Debit | D131: 500 | E131: Cleaning
A132: 46010 | B132: Check 2105 | C132: M D Wiring | D132: 500
A133: 46013 | B133: Check 2108 | C133: Vulcon Innovation | D133: 250
A134: 46013 | B134: Check 1322 | C134: M F Painting LLC | D134: 3000
A135: 46021 | B135: Check 1327 | C135: Vulcon Innovation | D135: 250
A136: 46021 | B136: Check 1326 | C136: Yhon Osocio | D136: 1500
A137: 46024 | B137: Check 8005 | C137: Tor Shower Door | D137: 2600
A138: 46043 | B138: Debit | C138: 2754 to 2424 | D138: 107.15
A139: 46043 | B139: Debit | C139: 2754 to 3448 | D139: 3742.16
A140: 46048 | B140: Check 2116 | C140: Vulcon Innovation | D140: 500
A141: 46058 | B141: Check 1330 | C141: L M Design Studio | D141: 2962.5
A142: 46070 | B142: Check 1333 | C142: Frank Verbout | D142: 4500
A143: 46076 | B143: Check 1335 | C143: American Marble Granite | D143: 500
... A148: 46251 | B148: Debit | C148: 2754 to 3448 | D148: 70000

Sheet Labour
A1: Date | B1: Mode | C1: Description | D1: Amount | F1: Total | G1: =sum(D2:D100006) -> 218654.18
A2: 45390 | B2: Check 2004 | C2: Luis Angel Rimacachin | D2: 130
A3: 45390 | B3: Check 2006 | C3: Juan minim | D3: 150
A4: 45390 | B4: Check 2005 | C4: Macuin Chonay | D4: 130
A5: 45404 | B5: Check 2008 | C5: Juan minim | D5: 250
A6: 45420 | B6: Check 2013 | C6: Frank Verbout | D6: 1025
A7: 45492 | B7: Check 1002 | C7: Juan minim | D7: 200
A8: 45502 | B8: Check 1003 | C8: Javier Alejandro Omaza | D8: 193
A9: 45530 | B9: Check 2029 | C9: Javier Alejandro Omaza | D9: 151.19
A10: 45530 | B10: Check 2025 | C10: Nilson Mocalos | D10: 310
A11: 45530 | B11: Check 2027 | C11: Carlos Chipix | D11: 465
A12: 45530 | B12: Check 2028 | C12: Javier Alejandro Omaza | D12: 545
A13: 45530 | B13: Check 2030 | C13: Crisanto cum Plato | D13: 740
... A329: 46118 | B329: Check 1343 | C329: Javier Alejandro Omaza | D329: 165

Sheet Bank fees
A1: Date | B1: Description | C1: Amount
A2: 45274 | B2: Wire Fees | C2: 20 | F2: Total | G2: =SUM(C2:C1003) -> 890
A3: 45638 | B3: Wire Fees | C3: 20
A4: 45300 | B4: Chargeback fees | C4: 20
A5: 45303 | B5: Wire Fees | C5: 20
A6: 45384 | B6: Wire Fees | C6: 20
A7: 45470 | B7: Overdraft Item Charge | C7: 20
A8: 45488 | B8: Overdraft Item Charge | C8: 20
A9: 45534 | B9: Wire Fees | C9: 10
A10: 45572 | B10: Wire Fees | C10: 10
A11: 45602 | B11: Wire Fees | C11: 10
A12: 45602 | B12: Wire Fees | C12: 10
A13: 45695 | B13: Wire Fees | C13: 10
A14: 45706 | B14: Outgoing Wire Fee | C14: 35
... A56: 46268 | B56: Wire Fees | C56: 10

Sheet Muncipality Expenses
A1: Date | B1: Description | C1: Amount
A2: 45362 | B2: NJ Web PMT | C2: 1125 | E2: Total | F2: =sum(C2:C10004) -> 27538.5
A3: 45379 | B3: JC Tax Fee | C3: 0.5
A4: 45379 | B4: JC Tax | C4: 5406.84
A5: 45384 | B5: Passaic Valley Sewage | C5: 3092.5
A6: 45511 | B6: Jercey City CFee | C6: 0.5
A7: 45511 | B7: Jercey City Tax Payment | C7: 5411.66
A8: 45520 | B8: Buider Capital | C8: 10000
A9: 45589 | B9: NJ Gov Serve | C9: 101
A10: 45726 | B10: NJ WEb PMT | C10: 975
A11: 45804 | B11: Juan Minin | C11: 350
A12: 46024 | B12: NJ Gov Serve | C12: 175.5
A13: 46091 | B13: Nj WEb PMT | C13: 900

Sheet Land acquisition
A1: Date | B1: Description | C1: Amount
A2: 45237 | B2: Closing for property | C2: 110000 | E2: Total | F2: =sum(C2:C999) -> 624823.01
A3: 45261 | B3: Closing for property | C3: 100000
A4: 45301 | B4: Checking Withdrawal | C4: 374823.01
A5: 45303 | B5: Wire transfer SunnySide Title | C5: 40000
O21: 110000

Sheet Loan Payment
A1: Date | B1: Description | C1: Amount
A2: 45372 | B2: Check 1001 FCI Lender Service | C2: 6524.97 | E2: Total | F2: =sum(C2:C24) -> 200850.02
A3: 45378 | B3: FCI Lender Service | C3: 5931.79 | E3: Total Interest Paid | F3: =C26 -> 268177.22
A4: 45411 | B4: FCI Lender Service | C4: 5931.79
A5: 45440 | B5: FCI Lender Service | C5: 5931.79
A6: 45470 | B6: FCI Lender Service | C6: 5931.79
A7: 45502 | B7: FCI Lender Service | C7: 5931.79
A8: 45531 | B8: FCI Lender Service | C8: 5931.79
A9: 45562 | B9: FCI Lender Service | C9: 6179.88
A10: 45593 | B10: FCI Lender Service | C10: 6969.63 | E10: Final Summary
A11: 45623 | B11: FCI Lender Service | C11: 8030.06 | E11: Category | F11: Amount
A12: 45653 | B12: FCI Lender Service | C12: 8179.71 | E12: Interest Paid Before Mar 2025 | F12: 88527
A13: 45684 | B13: FCI Lender Service | C13: 8179.71 | E13: Interest Paid Mar 2025–Mar 2026 | F13: 165600.53
A14: 45715 | B14: FCI Lender Service | C14: 8873.04 | E14: Fees & Charges | F14: 14049.69
A15: 45743 | B15: FCI Lender Service | C15: 9483.68
A16: 45775 | B16: FCI Lender Service | C16: 10957.38 | E16: ✅ Total Interest + Fees Paid:
A17: 45804 | B17: FCI Lender Service | C17: 11394.43
A18: 45835 | B18: FCI Lender Service | C18: 11652.77 | E18: 268177.22
A19: 45852 | B19: FCI Lender Service | C19: 5756.5
A20: 45887 | B20: FCI Lender Service | C20: 11923.44
A21: 45887 | B21: FCI Lender Service | C21: 11923.44
A22: 45896 | B22: FCI Lender Service | C22: 12506.54
A23: 45929 | B23: FCI Lender Service | C23: 13102.23
A24: 45980 | B24: FCI Lender Service | C24: 13621.87
B26: Final Interest payment | C26: 268177.22

Sheet Misc.
A1: Date | B1: Description | C1: MODE | D1: Amount | F1: Total | G1: =sum(D2:D9991) -> 65.77
A2: 45666 | B2: Deposit | C2: Credit | D2: -50000 | E2: Wash out
A3: 45666 | B3: Chargeback serial | C3: Debit | D3: 50000 | E3: Wash out
A4: 45244 | B4: Bus Prods for checks | D4: 36.14
A5: 45471 | B5: 1913 to 2754 | C5: Credit | D5: -6000 | E5: Wash out
A6: 45489 | B6: 2754 as per kunal | C6: Credit | D6: -5000 | E6: Wash out
A7: 45502 | B7: 1855 to 2754 | C7: Credit | D7: -5000 | E7: Wash out
A8: 45523 | B8: 2754 to 1855 | C8: Debit | D8: 5000 | E8: Wash out
A9: 45523 | B9: 2754 to 1913 | C9: Debit | D9: 5000 | E9: Wash out
A10: 45523 | B10: 2754 to 1913 | C10: Debit | D10: 6000 | E10: Wash out
A11: 45566 | B11: Point Grande | C11: Credit | E11: -25000 (Cash Swap Harshad)????
A12: 45666 | B12: Friend Of Anand Shah | C12: Check 2054 | D12: 500 | E12: donation
A13: 45714 | B13: Builder to Condo | C13: Debit | D13: 100 | E13: fee
A14: 45737 | B14: Withdrawal | C14: Debit | D14: 300 | E14: cleanign
A15: 45908 | B15: Diamond Agency | C15: Check 2061 | D15: 700 | E15: Rent
A16: 46080 | B16: Deposit | C16: Credit | D16: -3500 | E16: Wash out
A17: 46080 | B17: Withdrawal | C17: Debit | D17: 600
A18: 46080 | B18: Withdrawal | C18: Debit | D18: 3500 | E18: Wash out
A19: 46090 | B19: 2754 to 2424 | C19: Debit | D19: 13000
A20: 46091 | B20: Wire Transfer | C20: Debit | D20: 30
A21: 46125 | B21: Fci loan Payment | C21: Credit | D21: -3200.37
A22: 46136 | B22: Deposit | C22: Credit | D22: -12000

Sheet Personal Loan
A1: Date | B1: Mode | C1: Discription | D1: Amount
A2: 45565 | B2: Credit | C2: Deposite | D2: 525000
A5: Kunal Shah
A6: 46079 | B6: Debit | C6: Withdrawal | D6: 12750
A10: Piyush Patel To Builders
A11: 45967 | B11: Credit | C11: Piyush Patel | D11: 210000
A12: 45967 | B12: Credit | C12: Piyush Patel | D12: 140000
A13: 45667 | B13: Credit | C13: Piyush Patel | D13: 175000
A14: 45874 | B14: Credit | C14: Piyush Patel | D14: 80000
A15: 45925 | B15: Check 1020 | C15: Piyush Patel | D15: -80000
A16: 45932 | B16: Check 1021 | C16: Piyush Patel | D16: -525000
C17: Total | D17: =sum(D11:D16) -> 0

Sheet Accounting &legal fee
A1: Date | B1: Description | C1: Mode | D1: Amount
A2: 45349 | B2: Ami CPA | D2: 500 | F2: TOTAL | G2: =sum(D2:D99) -> 3500
A3: 45660 | B3: Ami CPA | D3: 300
A4: 45660 | B4: Ami CPA | D4: 650
A5: 45714 | B5: Ami CPA | D5: 1000
A6: 46204 | B6: Ami CPA | D6: 1050
